Workbook

Sheet Overview
A1: Kilimanjaro Half Marathon Plan — 29 Oct 2026 to 7 Feb 2027
A2: Yellow cells are yours to fill in. Everything else updates itself. Full explanations are in the plan document.
A4: Your numbers
A5: Start weight (kg) | B5: 87 | C5: You, 29 Oct 2026
A6: Height (m) | B6: 1.62 | C6: You
A7: Age | B7: 26 | C7: You, earlier
A8: Activity factor before training | B8: 1.2 | C8: Desk job (assumption)
A9: Race date | B9: 46425 | C9: Kilimanjaro Half Marathon, Moshi, 07:00 start
A10: Race cut-off (clock time) | B10: 12:30 | C10: Organiser's race info page
A12: Calculated
A13: BMI | B13: =B5/B6^2 -> 33.150434 | C13: Screening number only; waist tells you more
A14: Resting energy, Mifflin–St Jeor (kcal) | B14: =10*B5+6.25*B6*100-5*B7+5 -> 1757.5 | C14: Starting estimate, about ±10%
A15: Needs before training (kcal) | B15: =B14*B8 -> 2109 | C15: Training adds about 250–450 kcal a day
A16: Pace needed for 3:00 (min per km) | B16: =180/21.0975/1440 -> 0.0059248726 | C16: A maths reference, not your current pace
A17: Today's projection from a 60-min 5 km | B17: =60*(21.0975/5)^1.06*1.08/1440 -> 0.20700897 | C17: Riegel × 1.08 for hills, heat, beginner
A19: Progress dashboard (updates from the Daily Plan, Daily Log and Weekly Review sheets)
A20: Days to race | B20: =MAX(0,B9-TODAY()) -> 101
A21: Latest 7-day average weight (kg) | B21: =IFERROR(LOOKUP(2,1/ISNUMBER('Daily Log'!F5:F106),'Daily Log'!F5:F106),"Log your weight") -> Log your weight
A22: Change from start (kg) | B22: =IFERROR(B21-B5,"")
A23: Sessions done | B23: =COUNTIF('Daily Plan'!K:K,"Yes")+COUNTIF('Daily Plan'!K:K,"Partial") -> 0
A24: Sessions planned (whole plan) | B24: =COUNTIFS('Daily Plan'!F:F,"<>Rest",'Daily Plan'!F:F,"<>Type",'Daily Plan'!F:F,"<>") -> 142
A25: Completion | B25: =IFERROR(B23/B24,0) -> 0
A26: Longest run-walk logged (min) | B26: =_xlfn.MAXIFS('Daily Plan'!L:L,'Daily Plan'!F:F,"Run") -> 0
A27: Longest continuous swim logged (m) | B27: =MAX('Weekly Review'!T:T) -> 0
A28: Latest 5 km test (min) | B28: =IFERROR(LOOKUP(2,1/ISNUMBER('Weekly Review'!U5:U19),'Weekly Review'!U5:U19),"Not tested yet") -> Not tested yet
A29: Race projection from latest test | B29: =IFERROR(B28*(21.0975/5)^1.06*1.08/1440,"")
A30: Suggested race plan | B30: =IFERROR(LOOKUP(B28,{0,36.01,40.01,43.01,47.01},{"3:00","3:15","3:30","3:45","Finish strong (4:00)"}),"After your first test") -> After your first test
A31: This week's decision | B31: =IFERROR(INDEX('Weekly Review'!V5:V19,MATCH(MAX(0,MIN(14,INT((TODAY()-DATE(2026,11,2))/7)+1)),'Weekly Review'!A5:A19,0)),"")
A33: Phases
A34: Phase | B34: Weeks | C34: Dates | D34: Focus
A35: Foundation and movement adaptation | B35: 0–4 | C35: 29 Oct–29 Nov | D35: Short run intervals, strength habits, first swims, first 5 km test
A36: Aerobic development | B36: 5–8 | C36: 30 Nov–27 Dec | D36: Longer run intervals, strides, first hill walks, second test
A37: Race-specific endurance | B37: 9–11 | C37: 28 Dec–17 Jan | D37: Steady blocks, hill repeats, long sessions to 2 hours, deciding test
A38: Peak | B38: 12 | C38: 18–24 Jan | D38: 2 h 30 min race rehearsal with race fuelling
A39: Taper and race | B39: 13–14 | C39: 25 Jan–7 Feb | D39: Less volume, same rhythm, travel, race
A41: How to use this workbook
A42: Daily Plan | B42: Every session, 29 Oct–7 Feb, written out in full. After each one fill the yellow cells: Done (Yes, Partial, No), minutes, distance, RPE 1–10, notes.
A43: Example Daily Plan entry | B43: Done: Yes · Minutes: 32 · Distance: 3.1 · RPE: 4 · Notes: humid, extra walk break at 20 min
A44: Daily Log | B44: Every morning: weight, resting pulse, sleep, soreness, pain, energy, mood, motivation, nutrition and fasting scores. The 7-day average weight calculates itself.
A45: Example Daily Log entry | B45: Weight 86.6 · Pulse 64 · Sleep 7.0 h, quality 4 · Soreness 2 · Pain 0 · Energy 4 · Mood 4 · Motivation 4 · Nutrition 4
...

Sheet Daily Plan
A1: Daily Plan — every session, 29 October 2026 to 7 February 2027
A2: Fill the yellow columns after each session. Done: Yes / Partial / No. Minutes = total time. Distance in km for runs, m for swims.
A4: Date | B4: Week | C4: Day | D4: Phase | E4: Time | F4: Type | G4: Session | H4: Full details | I4: Planned | J4: Unit | K4: Done | L4: Minutes | M4: Distance | N4: RPE (1–10) | O4: Notes
A5: 46324 | B5: 0 | C5: Thursday | D5: Foundation | E5: After iftar (about 20:15) | F5: Mobility | G5: FAST DAY — Easy walk 20 min + mobility | H5: Dry-fast day: NO exercise while fasting. 18:50 break the fast (500 ml water, 3 dates, soup), 19:20 main meal. About 20:15: easy walk 20 min (RPE 2, flat, conversational) then fast-day mobility 15 min: cat-cow 8, thread the needle 6 per side, 90/90 hip switches 10, couch stretch 45 s per side, calf stretch 45 s per leg, child's pose 60 s. Finish with 5 min slow breathing: in through the nose 4 s, out 6 s. Keep sipping water until bed. Skip the walk if you feel dizzy, have a headache or are very tired; do the mobility and breathing only. | I5: 40 | J5: min
A6: 46325 | B6: 0 | C6: Friday | D6: Foundation | E6: Morning | F6: Run | G6: Run-walk 30 min | H6: Purpose: build aerobic endurance and impact tolerance. Warm-up: 5 min brisk walk, then leg swings 10 per leg each way, walking lunges 8 per leg, ankle rocks 10 per side, 2 × 20 m easy skipping. Main: run 1 min / walk 2 min, repeated 7 times (about 21 min). Intensity: easy, RPE 3–4 out of 10. You can talk in full sentences. If you cannot, walk more. Running form: short quick steps, tall posture, relaxed shoulders. Cool-down: 5 min easy walk, then calf stretch 45 s per leg, standing quad stretch 45 s per leg, hamstring stretch 45 s per leg, figure-four glute stretch 45 s per side. Total about 30 min. If unusually tired, sore, dizzy or you slept under 6 hours: do the same time as brisk walking only, or swap for 20–30 min walking. Pain that changes your stride: stop and walk home. Start before 06:30. Carry water. On hot, humid mornings, slow down rather than speed up. | I6: 30 | J6: min
A7: 46326 | B7: 0 | C7: Saturday | D7: Foundation | E7: Morning | F7: Run | G7: Long run-walk 40 min (≈ 3 km) | H7: Purpose: build the endurance to cover 21.1 km. Start at first light (about 05:45). Warm-up: 5 min brisk walk, then leg swings 10 per leg each way, walking lunges 8 per leg, ankle rocks 10 per side, 2 × 20 m easy skipping. Main: run 1 min / walk 2 min for 40 min, effort RPE 3–4 the whole way: the last 20 minutes should feel as easy as the first. Fuel: water before and after is enough. Cool-down: 5 min easy walk, then calf stretch 45 s per leg, standing quad stretch 45 s per leg, hamstring stretch 45 s per leg, figure-four glute stretch 45 s per side. Progress next week only if you finished with no pain and felt recovered within 24 hours; otherwise repeat this week's length. If unusually tired, sore, dizzy or you slept under 6 hours: do the same time as brisk walking only, or swap for 20–30 min walking. Pain that changes your stride: stop and walk home. Start before 06:30. Carry water. On hot, humid mornings, slow down rather than speed up. | I7: 40 | J7: min
A8: 46327 | B8: 0 | C8: Sunday | D8: Foundation | E8: Evening | F8: Swim | G8: Swim — 100 m continuous (easy) | H8: Purpose: recovery from the long run and longer continuous swimming. Warm-up: 4 × 25 m easy (any stroke), 20–30 s rest at the wall. Drills: 4 × 25 m — side kick with one arm forward, catch-up freestyle, fingertip drag, six-kick switch (rest 20–30 s each). Breathe out steadily under water; roll to breathe. Main: 100 m continuous, very easy (RPE 3–4): stop and rest 20–30 s if you must, then finish the distance; record the longest distance you swam without stopping. Then 4 × 50 m relaxed with 30 s rest. Cool-down: 50–100 m very easy backstroke or breaststroke, then shoulder and chest stretches 30 s each. Total about 600 m. Optional session: skip it if the pool is unavailable or you feel run-down. Never swim alone where there is no lifeguard. | I8: 600 | J8: m
A9: 46327 | B9: 0 | C9: Sunday | D9: Foundation | E9: Any time | F9: Mobility | G9: Recovery walk + mobility | H9: Recovery after the long run: 20 min easy walk plus 10 min of the fast-day mobility routine. No extra training for calories. | I9: 30 | J9: min
A10: 46328 | B10: 1 | C10: Monday | D10: Foundation | E10: After iftar (about 20:15) | F10: Mobility | G10: FAST DAY — Easy walk 20 min + mobility | H10: Dry-fast day: NO exercise while fasting. 18:50 break the fast (500 ml water, 3 dates, soup), 19:20 main meal. About 20:15: easy walk 20 min (RPE 2, flat, conversational) then fast-day mobility 15 min: cat-cow 8, thread the needle 6 per side, 90/90 hip switches 10, couch stretch 45 s per side, calf stretch 45 s per leg, child's pose 60 s. Finish with 5 min slow breathing: in through the nose 4 s, out 6 s. Keep sipping water until bed. Skip the walk if you feel dizzy, have a headache or are very tired; do the mobility and breathing only. | I10: 40 | J10: min
A11: 46329 | B11: 1 | C11: Tuesday | D11: Foundation | E11: Morning | F11: Run | G11: Run-walk 30 min | H11: Purpose: build aerobic endurance and impact tolerance. Warm-up: 5 min brisk walk, then leg swings 10 per leg each way, walking lunges 8 per leg, ankle rocks 10 per side, 2 × 20 m easy skipping. Main: run 1 min / walk 2 min, repeated 7 times (about 21 min). Intensity: easy, RPE 3–4 out of 10. You can talk in full sentences. If you cannot, walk more. Running form: short quick steps, tall posture, relaxed shoulders. Cool-down: 5 min easy walk, then calf stretch 45 s per leg, standing quad stretch 45 s per leg, hamstring stretch 45 s per leg, figure-four glute stretch 45 s per side. Total about 30 min. If unusually tired, sore, dizzy or you slept under 6 hours: do the same time as brisk walking only, or swap for 20–30 min walking. Pain that changes your stride: stop and walk home. Start before 06:30. Carry water. On hot, humid mornings, slow down rather than speed up. | I11: 30 | J11: min
A12: 46329 | B12: 1 | C12: Tuesday | D12: Foundation | E12: Evening | F12: Strength | G12: Strength B — upper body, feet, balance | H12: Strength B — upper body, feet and balance (about 25 min). Warm-up 5 min: arm circles 10 each way, cat-cow 8, bodyweight squats 10, single-leg stands 20 s per leg. Then: 1) Push-up progression: wall → table (incline) → knees → full — 3 × 8–12. 2) Backpack bent-over row (5–10 kg of books or bottles) — 3 × 10–12. 3) Backpack overhead press, or pike push-up — 3 × 8–10. 4) Single-leg balance: 30 s per leg, then eyes closed, then on a folded towel — 3 rounds. 5) Slow single-leg calf lowering (up on two legs, down on one over 3 s) — 2 × 10 per leg. 6) Foot strength: towel scrunches 2 × 20 and tibialis raises (back to a wall, lift toes) 2 × 15. 7) Bird dog — 3 × 8 per side; front plank — 3 × 20–45 s. Finish: pelvic-floor block — 10 slow squeezes held 5 s in a deep squat hold. Effort RPE 6–7; legs stay fresh for Friday and Saturday. If sore or tired: do 1 set of each and skip anything that hurts. Pain above 3/10 that rises during a set: stop that exercise. | I12: 25 | J12: min
A13: 46330 | B13: 1 | C13: Wednesday | D13: Foundation | E13: Afternoon | F13: Strength | G13: Strength A — legs, hips, trunk | H13: Strength A — legs, hips and trunk (about 30 min). Warm-up 5 min: march on the spot 1 min, hip circles 10 each way, bodyweight squats 10, glute bridges 10, inchworms 5. Then: 1) Sit-to-stand from a chair, progressing to bodyweight squat then backpack squat — 3 × 8–12, rest 60–90 s. 2) Glute bridge, progressing to single-leg bridge — 3 × 10–12 (2-second squeeze at top). 3) Step-ups on a safe 20–30 cm step, or reverse lunges holding a wall — 3 × 8 per leg. 4) Hip hinge: hands-on-hips good morning, progressing to single-leg Romanian deadlift with a hand on a wall, then holding the backpack — 3 × 10 (per leg when single-leg). 5) Calf raises on a step edge: both legs, progressing to single-leg; 3-second lowering — 3 × 12–15. 6) Bent-knee calf raise (soleus) — 2 × 15. 7) Dead bug — 3 × 8 per side; side plank — 3 × 20–40 s per side. Finish: pelvic-floor block — glute bridge with a 5-second pelvic-floor squeeze, 10 reps. Effort: stop each set with 2–3 reps left (RPE 7). Never to failure. Cool-down: quad, hamstring and calf stretches 30–45 s each. If sore or tired: do 1 set of each and skip anything that hurts. Pain above 3/10 that rises during a set: stop that exercise. | I13: 30 | J13: min
A14: 46330 | B14: 1 | C14: Wednesday | D14: Foundation | E14: Evening | F14: Swim | G14: Swim — 8 × 50 m repeats | H14: Purpose: low-impact aerobic fitness and relaxed breathing. Warm-up: 4 × 25 m easy (any stroke), 20–30 s rest at the wall. Drills: 4 × 25 m — side kick with one arm forward, catch-up freestyle, fingertip drag, six-kick switch (rest 20–30 s each). Breathe out steadily under water; roll to breathe. Main: 8 × 50 m freestyle at easy-to-steady effort (RPE 4–5), 40 s rest between. Cool-down: 50–100 m very easy backstroke or breaststroke, then shoulder and chest stretches 30 s each. Total about 700 m, 30–40 min. Optional session: skip it if the pool is unavailable or you feel run-down. Never swim alone where there is no lifeguard. | I14: 700 | J14: m
A15: 46331 | B15: 1 | C15: Thursday | D15: Foundation | E15: After iftar (about 20:15) | F15: Mobility | G15: FAST DAY — Easy walk 20 min + mobility | H15: Dry-fast day: NO exercise while fasting. 18:50 break the fast (500 ml water, 3 dates, soup), 19:20 main meal. About 20:15: easy walk 20 min (RPE 2, flat, conversational) then fast-day mobility 15 min: cat-cow 8, thread the needle 6 per side, 90/90 hip switches 10, couch stretch 45 s per side, calf stretch 45 s per leg, child's pose 60 s. Finish with 5 min slow breathing: in through the nose 4 s, out 6 s. Keep sipping water until bed. Skip the walk if you feel dizzy, have a headache or are very tired; do the mobility and breathing only. | I15: 40 | J15: min
A16: 46332 | B16: 1 | C16: Friday | D16: Foundation | E16: Morning | F16: Run | G16: Run-walk 30 min | H16: Purpose: build aerobic endurance and impact tolerance. Warm-up: 5 min brisk walk, then leg swings 10 per leg each way, walking lunges 8 per leg, ankle rocks 10 per side, 2 × 20 m easy skipping. Main: run 1 min / walk 2 min, repeated 7 times (about 21 min). Intensity: easy, RPE 3–4 out of 10. You can talk in full sentences. If you cannot, walk more. Running form: short quick steps, tall posture, relaxed shoulders. Cool-down: 5 min easy walk, then calf stretch 45 s per leg, standing quad stretch 45 s per leg, hamstring stretch 45 s per leg, figure-four glute stretch 45 s per side. Total about 30 min. If unusually tired, sore, dizzy or you slept under 6 hours: do the same time as brisk walking only, or swap for 20–30 min walking. Pain that changes your stride: stop and walk home. Start before 06:30. Carry water. On hot, humid mornings, slow down rather than speed up. | I16: 30 | J16: min
... A147: 46425 | B147: 14 | C147: Sunday | D147: Race week | E147: Morning | F147: Run | G147: RACE — Kilimanjaro Half Marathon 21.1 km | H147: Race day: start 07:00 at MoCU Gate, Sokoine Road, Moshi; cut-off 12:30. Follow the race plan in section 15: breakfast at about 04:00, start slower than feels right, walk the steep parts of the 8 km climb, carbohydrate every 20–25 min, drink to thirst at every water point. Enjoy it. | I147: 21.1 | J147: km

Sheet Daily Log
A1: Daily Log — two minutes every morning
A2: Weight after the toilet, before food or drink. Scores: soreness and pain 0–10; others 1–5 (5 = best). Fasting tolerance only on Mon and Thu.
A4: Date | B4: Week | C4: Day | D4: Fast day | E4: Weight (kg) | F4: 7-day avg (kg) | G4: Resting pulse | H4: Sleep (h) | I4: Sleep quality 1–5 | J4: Soreness 0–10 | K4: Pain 0–10 | L4: Pain where | M4: Energy 1–5 | N4: Mood 1–5 | O4: Motivation 1–5 | P4: Nutrition 1–5 | Q4: Fasting tolerance 1–5 | R4: Warning signs (Yes/No) | S4: Notes
A5: 46324 | B5: 0 | C5: Thursday | D5: Yes | F5: =IF(COUNT(E5:E5)=0,"",AVERAGE(E5:E5))
A6: 46325 | B6: 0 | C6: Friday | F6: =IF(COUNT(E5:E6)=0,"",AVERAGE(E5:E6)) | Q6: —
A7: 46326 | B7: 0 | C7: Saturday | F7: =IF(COUNT(E5:E7)=0,"",AVERAGE(E5:E7)) | Q7: —
A8: 46327 | B8: 0 | C8: Sunday | F8: =IF(COUNT(E5:E8)=0,"",AVERAGE(E5:E8)) | Q8: —
A9: 46328 | B9: 1 | C9: Monday | D9: Yes | F9: =IF(COUNT(E5:E9)=0,"",AVERAGE(E5:E9))
A10: 46329 | B10: 1 | C10: Tuesday | F10: =IF(COUNT(E5:E10)=0,"",AVERAGE(E5:E10)) | Q10: —
A11: 46330 | B11: 1 | C11: Wednesday | F11: =IF(COUNT(E5:E11)=0,"",AVERAGE(E5:E11)) | Q11: —
A12: 46331 | B12: 1 | C12: Thursday | D12: Yes | F12: =IF(COUNT(E6:E12)=0,"",AVERAGE(E6:E12))
A13: 46332 | B13: 1 | C13: Friday | F13: =IF(COUNT(E7:E13)=0,"",AVERAGE(E7:E13)) | Q13: —
A14: 46333 | B14: 1 | C14: Saturday | F14: =IF(COUNT(E8:E14)=0,"",AVERAGE(E8:E14)) | Q14: —
A15: 46334 | B15: 1 | C15: Sunday | F15: =IF(COUNT(E9:E15)=0,"",AVERAGE(E9:E15)) | Q15: —
A16: 46335 | B16: 2 | C16: Monday | D16: Yes | F16: =IF(COUNT(E10:E16)=0,"",AVERAGE(E10:E16))
A17: 46336 | B17: 2 | C17: Tuesday | F17: =IF(COUNT(E11:E17)=0,"",AVERAGE(E11:E17)) | Q17: —
A18: 46337 | B18: 2 | C18: Wednesday | F18: =IF(COUNT(E12:E18)=0,"",AVERAGE(E12:E18)) | Q18: —
A19: 46338 | B19: 2 | C19: Thursday | D19: Yes | F19: =IF(COUNT(E13:E19)=0,"",AVERAGE(E13:E19))
A20: 46339 | B20: 2 | C20: Friday | F20: =IF(COUNT(E14:E20)=0,"",AVERAGE(E14:E20)) | Q20: —
A21: 46340 | B21: 2 | C21: Saturday | F21: =IF(COUNT(E15:E21)=0,"",AVERAGE(E15:E21)) | Q21: —
A22: 46341 | B22: 2 | C22: Sunday | F22: =IF(COUNT(E16:E22)=0,"",AVERAGE(E16:E22)) | Q22: —
A23: 46342 | B23: 3 | C23: Monday | D23: Yes | F23: =IF(COUNT(E17:E23)=0,"",AVERAGE(E17:E23))
A24: 46343 | B24: 3 | C24: Tuesday | F24: =IF(COUNT(E18:E24)=0,"",AVERAGE(E18:E24)) | Q24: —
A25: 46344 | B25: 3 | C25: Wednesday | F25: =IF(COUNT(E19:E25)=0,"",AVERAGE(E19:E25)) | Q25: —
A26: 46345 | B26: 3 | C26: Thursday | D26: Yes | F26: =IF(COUNT(E20:E26)=0,"",AVERAGE(E20:E26))
A27: 46346 | B27: 3 | C27: Friday | F27: =IF(COUNT(E21:E27)=0,"",AVERAGE(E21:E27)) | Q27: —
A28: 46347 | B28: 3 | C28: Saturday | F28: =IF(COUNT(E22:E28)=0,"",AVERAGE(E22:E28)) | Q28: —
A29: 46348 | B29: 3 | C29: Sunday | F29: =IF(COUNT(E23:E29)=0,"",AVERAGE(E23:E29)) | Q29: —
A30: 46349 | B30: 4 | C30: Monday | D30: Yes | F30: =IF(COUNT(E24:E30)=0,"",AVERAGE(E24:E30))
A31: 46350 | B31: 4 | C31: Tuesday | F31: =IF(COUNT(E25:E31)=0,"",AVERAGE(E25:E31)) | Q31: —
A32: 46351 | B32: 4 | C32: Wednesday | F32: =IF(COUNT(E26:E32)=0,"",AVERAGE(E26:E32)) | Q32: —
A33: 46352 | B33: 4 | C33: Thursday | D33: Yes | F33: =IF(COUNT(E27:E33)=0,"",AVERAGE(E27:E33))
A34: 46353 | B34: 4 | C34: Friday | F34: =IF(COUNT(E28:E34)=0,"",AVERAGE(E28:E34)) | Q34: —
A35: 46354 | B35: 4 | C35: Saturday | F35: =IF(COUNT(E29:E35)=0,"",AVERAGE(E29:E35)) | Q35: —
A36: 46355 | B36: 4 | C36: Sunday | F36: =IF(COUNT(E30:E36)=0,"",AVERAGE(E30:E36)) | Q36: —
A37: 46356 | B37: 5 | C37: Monday | D37: Yes | F37: =IF(COUNT(E31:E37)=0,"",AVERAGE(E31:E37))
A38: 46357 | B38: 5 | C38: Tuesday | F38: =IF(COUNT(E32:E38)=0,"",AVERAGE(E32:E38)) | Q38: —
A39: 46358 | B39: 5 | C39: Wednesday | F39: =IF(COUNT(E33:E39)=0,"",AVERAGE(E33:E39)) | Q39: —
A40: 46359 | B40: 5 | C40: Thursday | D40: Yes | F40: =IF(COUNT(E34:E40)=0,"",AVERAGE(E34:E40))
A41: 46360 | B41: 5 | C41: Friday | F41: =IF(COUNT(E35:E41)=0,"",AVERAGE(E35:E41)) | Q41: —
...

Sheet Weekly Review
A1: Weekly Review — the Sunday decision
A2: Fill waist, swim and any 5 km test (yellow). Decision: Green = progress, Amber = repeat the week, Red = step back (plan section 14).
A4: Week | B4: Starts | C4: Phase | D4: Sessions planned | E4: Sessions done | F4: Completion | G4: Run min planned | H4: Run min done | I4: Long session planned (min) | J4: Long session done (min) | K4: Avg run RPE | L4: Avg sleep (h) | M4: Avg sleep quality | N4: Max pain | O4: Avg energy | P4: Avg mood | Q4: Avg weight (kg) | R4: Change (kg) | S4: Waist (cm) | T4: Swim continuous (m) | U4: 5 km test (min) | V4: Decision | W4: Notes
A5: 0 | B5: 46324 | C5: Foundation | D5: =COUNTIFS('Daily Plan'!$B$5:$B$147,A5,'Daily Plan'!$F$5:$F$147,"<>Rest") -> 5 | E5: =COUNTIFS('Daily Plan'!$B$5:$B$147,A5,'Daily Plan'!$K$5:$K$147,"Yes")+COUNTIFS('Daily Plan'!$B$5:$B$147,A5,'Daily Plan'!$K$5:$K$147,"Partial") -> 0 | F5: =IFERROR(E5/D5,"") -> 0 | G5: =SUMIFS('Daily Plan'!$I$5:$I$147,'Daily Plan'!$B$5:$B$147,A5,'Daily Plan'!$F$5:$F$147,"Run",'Daily Plan'!$J$5:$J$147,"min") -> 70 | H5: =SUMIFS('Daily Plan'!$L$5:$L$147,'Daily Plan'!$B$5:$B$147,A5,'Daily Plan'!$F$5:$F$147,"Run") -> 0 | I5: 40 | J5: =IFERROR(INDEX('Daily Plan'!$L$5:$L$147,MATCH(1,INDEX(('Daily Plan'!$B$5:$B$147=A5)*('Daily Plan'!$C$5:$C$147="Saturday")*('Daily Plan'!$F$5:$F$147="Run"),0),0)),"") -> 0 | K5: =IFERROR(AVERAGEIFS('Daily Plan'!$N$5:$N$147,'Daily Plan'!$B$5:$B$147,A5,'Daily Plan'!$F$5:$F$147,"Run"),"") | L5: =IFERROR(AVERAGEIFS('Daily Log'!$H$5:$H$106,'Daily Log'!$B$5:$B$106,A5),"") | M5: =IFERROR(AVERAGEIFS('Daily Log'!$I$5:$I$106,'Daily Log'!$B$5:$B$106,A5),"") | N5: =IF(COUNTIFS('Daily Log'!$B$5:$B$106,A5,'Daily Log'!$K$5:$K$106,">=0")=0,"",_xlfn.MAXIFS('Daily Log'!$K$5:$K$106,'Daily Log'!$B$5:$B$106,A5)) | O5: =IFERROR(AVERAGEIFS('Daily Log'!$M$5:$M$106,'Daily Log'!$B$5:$B$106,A5),"") | P5: =IFERROR(AVERAGEIFS('Daily Log'!$N$5:$N$106,'Daily Log'!$B$5:$B$106,A5),"") | Q5: =IFERROR(AVERAGEIFS('Daily Log'!$E$5:$E$106,'Daily Log'!$B$5:$B$106,A5),"") | V5: =IF(E5=0,"",IF(OR(AND(N5<>"",N5>=4),AND(F5<>"",F5<0.6),AND(L5<>"",L5<6)),"Red: step back",IF(OR(AND(F5<>"",F5<0.85),AND(K5<>"",K5>=5),AND(N5<>"",N5>=3),AND(L5<>"",L5<6.5),AND(O5<>"",O5<3),AND(P5<>"",P5<3)),"Amber: repeat the week","Green: progress")))
A6: 1 | B6: 46328 | C6: Foundation | D6: =COUNTIFS('Daily Plan'!$B$5:$B$147,A6,'Daily Plan'!$F$5:$F$147,"<>Rest") -> 10 | E6: =COUNTIFS('Daily Plan'!$B$5:$B$147,A6,'Daily Plan'!$K$5:$K$147,"Yes")+COUNTIFS('Daily Plan'!$B$5:$B$147,A6,'Daily Plan'!$K$5:$K$147,"Partial") -> 0 | F6: =IFERROR(E6/D6,"") -> 0 | G6: =SUMIFS('Daily Plan'!$I$5:$I$147,'Daily Plan'!$B$5:$B$147,A6,'Daily Plan'!$F$5:$F$147,"Run",'Daily Plan'!$J$5:$J$147,"min") -> 105 | H6: =SUMIFS('Daily Plan'!$L$5:$L$147,'Daily Plan'!$B$5:$B$147,A6,'Daily Plan'!$F$5:$F$147,"Run") -> 0 | I6: 45 | J6: =IFERROR(INDEX('Daily Plan'!$L$5:$L$147,MATCH(1,INDEX(('Daily Plan'!$B$5:$B$147=A6)*('Daily Plan'!$C$5:$C$147="Saturday")*('Daily Plan'!$F$5:$F$147="Run"),0),0)),"") -> 0 | K6: =IFERROR(AVERAGEIFS('Daily Plan'!$N$5:$N$147,'Daily Plan'!$B$5:$B$147,A6,'Daily Plan'!$F$5:$F$147,"Run"),"") | L6: =IFERROR(AVERAGEIFS('Daily Log'!$H$5:$H$106,'Daily Log'!$B$5:$B$106,A6),"") | M6: =IFERROR(AVERAGEIFS('Daily Log'!$I$5:$I$106,'Daily Log'!$B$5:$B$106,A6),"") | N6: =IF(COUNTIFS('Daily Log'!$B$5:$B$106,A6,'Daily Log'!$K$5:$K$106,">=0")=0,"",_xlfn.MAXIFS('Daily Log'!$K$5:$K$106,'Daily Log'!$B$5:$B$106,A6)) | O6: =IFERROR(AVERAGEIFS('Daily Log'!$M$5:$M$106,'Daily Log'!$B$5:$B$106,A6),"") | P6: =IFERROR(AVERAGEIFS('Daily Log'!$N$5:$N$106,'Daily Log'!$B$5:$B$106,A6),"") | Q6: =IFERROR(AVERAGEIFS('Daily Log'!$E$5:$E$106,'Daily Log'!$B$5:$B$106,A6),"") | R6: =IF(OR(Q6="",Q5=""),"",Q6-Q5) | V6: =IF(E6=0,"",IF(OR(AND(N6<>"",N6>=4),AND(F6<>"",F6<0.6),AND(L6<>"",L6<6)),"Red: step back",IF(OR(AND(F6<>"",F6<0.85),AND(K6<>"",K6>=5),AND(N6<>"",N6>=3),AND(L6<>"",L6<6.5),AND(O6<>"",O6<3),AND(P6<>"",P6<3)),"Amber: repeat the week","Green: progress")))
A7: 2 | B7: 46335 | C7: Foundation | D7: =COUNTIFS('Daily Plan'!$B$5:$B$147,A7,'Daily Plan'!$F$5:$F$147,"<>Rest") -> 10 | E7: =COUNTIFS('Daily Plan'!$B$5:$B$147,A7,'Daily Plan'!$K$5:$K$147,"Yes")+COUNTIFS('Daily Plan'!$B$5:$B$147,A7,'Daily Plan'!$K$5:$K$147,"Partial") -> 0 | F7: =IFERROR(E7/D7,"") -> 0 | G7: =SUMIFS('Daily Plan'!$I$5:$I$147,'Daily Plan'!$B$5:$B$147,A7,'Daily Plan'!$F$5:$F$147,"Run",'Daily Plan'!$J$5:$J$147,"min") -> 115 | H7: =SUMIFS('Daily Plan'!$L$5:$L$147,'Daily Plan'!$B$5:$B$147,A7,'Daily Plan'!$F$5:$F$147,"Run") -> 0 | I7: 50 | J7: =IFERROR(INDEX('Daily Plan'!$L$5:$L$147,MATCH(1,INDEX(('Daily Plan'!$B$5:$B$147=A7)*('Daily Plan'!$C$5:$C$147="Saturday")*('Daily Plan'!$F$5:$F$147="Run"),0),0)),"") -> 0 | K7: =IFERROR(AVERAGEIFS('Daily Plan'!$N$5:$N$147,'Daily Plan'!$B$5:$B$147,A7,'Daily Plan'!$F$5:$F$147,"Run"),"") | L7: =IFERROR(AVERAGEIFS('Daily Log'!$H$5:$H$106,'Daily Log'!$B$5:$B$106,A7),"") | M7: =IFERROR(AVERAGEIFS('Daily Log'!$I$5:$I$106,'Daily Log'!$B$5:$B$106,A7),"") | N7: =IF(COUNTIFS('Daily Log'!$B$5:$B$106,A7,'Daily Log'!$K$5:$K$106,">=0")=0,"",_xlfn.MAXIFS('Daily Log'!$K$5:$K$106,'Daily Log'!$B$5:$B$106,A7)) | O7: =IFERROR(AVERAGEIFS('Daily Log'!$M$5:$M$106,'Daily Log'!$B$5:$B$106,A7),"") | P7: =IFERROR(AVERAGEIFS('Daily Log'!$N$5:$N$106,'Daily Log'!$B$5:$B$106,A7),"") | Q7: =IFERROR(AVERAGEIFS('Daily Log'!$E$5:$E$106,'Daily Log'!$B$5:$B$106,A7),"") | R7: =IF(OR(Q7="",Q6=""),"",Q7-Q6) | V7: =IF(E7=0,"",IF(OR(AND(N7<>"",N7>=4),AND(F7<>"",F7<0.6),AND(L7<>"",L7<6)),"Red: step back",IF(OR(AND(F7<>"",F7<0.85),AND(K7<>"",K7>=5),AND(N7<>"",N7>=3),AND(L7<>"",L7<6.5),AND(O7<>"",O7<3),AND(P7<>"",P7<3)),"Amber: repeat the week","Green: progress")))
A8: 3 | B8: 46342 | C8: Foundation | D8: =COUNTIFS('Daily Plan'!$B$5:$B$147,A8,'Daily Plan'!$F$5:$F$147,"<>Rest") -> 10 | E8: =COUNTIFS('Daily Plan'!$B$5:$B$147,A8,'Daily Plan'!$K$5:$K$147,"Yes")+COUNTIFS('Daily Plan'!$B$5:$B$147,A8,'Daily Plan'!$K$5:$K$147,"Partial") -> 0 | F8: =IFERROR(E8/D8,"") -> 0 | G8: =SUMIFS('Daily Plan'!$I$5:$I$147,'Daily Plan'!$B$5:$B$147,A8,'Daily Plan'!$F$5:$F$147,"Run",'Daily Plan'!$J$5:$J$147,"min") -> 130 | H8: =SUMIFS('Daily Plan'!$L$5:$L$147,'Daily Plan'!$B$5:$B$147,A8,'Daily Plan'!$F$5:$F$147,"Run") -> 0 | I8: 60 | J8: =IFERROR(INDEX('Daily Plan'!$L$5:$L$147,MATCH(1,INDEX(('Daily Plan'!$B$5:$B$147=A8)*('Daily Plan'!$C$5:$C$147="Saturday")*('Daily Plan'!$F$5:$F$147="Run"),0),0)),"") -> 0 | K8: =IFERROR(AVERAGEIFS('Daily Plan'!$N$5:$N$147,'Daily Plan'!$B$5:$B$147,A8,'Daily Plan'!$F$5:$F$147,"Run"),"") | L8: =IFERROR(AVERAGEIFS('Daily Log'!$H$5:$H$106,'Daily Log'!$B$5:$B$106,A8),"") | M8: =IFERROR(AVERAGEIFS('Daily Log'!$I$5:$I$106,'Daily Log'!$B$5:$B$106,A8),"") | N8: =IF(COUNTIFS('Daily Log'!$B$5:$B$106,A8,'Daily Log'!$K$5:$K$106,">=0")=0,"",_xlfn.MAXIFS('Daily Log'!$K$5:$K$106,'Daily Log'!$B$5:$B$106,A8)) | O8: =IFERROR(AVERAGEIFS('Daily Log'!$M$5:$M$106,'Daily Log'!$B$5:$B$106,A8),"") | P8: =IFERROR(AVERAGEIFS('Daily Log'!$N$5:$N$106,'Daily Log'!$B$5:$B$106,A8),"") | Q8: =IFERROR(AVERAGEIFS('Daily Log'!$E$5:$E$106,'Daily Log'!$B$5:$B$106,A8),"") | R8: =IF(OR(Q8="",Q7=""),"",Q8-Q7) | V8: =IF(E8=0,"",IF(OR(AND(N8<>"",N8>=4),AND(F8<>"",F8<0.6),AND(L8<>"",L8<6)),"Red: step back",IF(OR(AND(F8<>"",F8<0.85),AND(K8<>"",K8>=5),AND(N8<>"",N8>=3),AND(L8<>"",L8<6.5),AND(O8<>"",O8<3),AND(P8<>"",P8<3)),"Amber: repeat the week","Green: progress")))
A9: 4 | B9: 46349 | C9: Foundation | D9: =COUNTIFS('Daily Plan'!$B$5:$B$147,A9,'Daily Plan'!$F$5:$F$147,"<>Rest") -> 10 | E9: =COUNTIFS('Daily Plan'!$B$5:$B$147,A9,'Daily Plan'!$K$5:$K$147,"Yes")+COUNTIFS('Daily Plan'!$B$5:$B$147,A9,'Daily Plan'!$K$5:$K$147,"Partial") -> 0 | F9: =IFERROR(E9/D9,"") -> 0 | G9: =SUMIFS('Daily Plan'!$I$5:$I$147,'Daily Plan'!$B$5:$B$147,A9,'Daily Plan'!$F$5:$F$147,"Run",'Daily Plan'!$J$5:$J$147,"min") -> 120 | H9: =SUMIFS('Daily Plan'!$L$5:$L$147,'Daily Plan'!$B$5:$B$147,A9,'Daily Plan'!$F$5:$F$147,"Run") -> 0 | I9: 45 | J9: =IFERROR(INDEX('Daily Plan'!$L$5:$L$147,MATCH(1,INDEX(('Daily Plan'!$B$5:$B$147=A9)*('Daily Plan'!$C$5:$C$147="Saturday")*('Daily Plan'!$F$5:$F$147="Run"),0),0)),"") -> 0 | K9: =IFERROR(AVERAGEIFS('Daily Plan'!$N$5:$N$147,'Daily Plan'!$B$5:$B$147,A9,'Daily Plan'!$F$5:$F$147,"Run"),"") | L9: =IFERROR(AVERAGEIFS('Daily Log'!$H$5:$H$106,'Daily Log'!$B$5:$B$106,A9),"") | M9: =IFERROR(AVERAGEIFS('Daily Log'!$I$5:$I$106,'Daily Log'!$B$5:$B$106,A9),"") | N9: =IF(COUNTIFS('Daily Log'!$B$5:$B$106,A9,'Daily Log'!$K$5:$K$106,">=0")=0,"",_xlfn.MAXIFS('Daily Log'!$K$5:$K$106,'Daily Log'!$B$5:$B$106,A9)) | O9: =IFERROR(AVERAGEIFS('Daily Log'!$M$5:$M$106,'Daily Log'!$B$5:$B$106,A9),"") | P9: =IFERROR(AVERAGEIFS('Daily Log'!$N$5:$N$106,'Daily Log'!$B$5:$B$106,A9),"") | Q9: =IFERROR(AVERAGEIFS('Daily Log'!$E$5:$E$106,'Daily Log'!$B$5:$B$106,A9),"") | R9: =IF(OR(Q9="",Q8=""),"",Q9-Q8) | V9: =IF(E9=0,"",IF(OR(AND(N9<>"",N9>=4),AND(F9<>"",F9<0.6),AND(L9<>"",L9<6)),"Red: step back",IF(OR(AND(F9<>"",F9<0.85),AND(K9<>"",K9>=5),AND(N9<>"",N9>=3),AND(L9<>"",L9<6.5),AND(O9<>"",O9<3),AND(P9<>"",P9<3)),"Amber: repeat the week","Green: progress")))
A10: 5 | B10: 46356 | C10: Aerobic development | D10: =COUNTIFS('Daily Plan'!$B$5:$B$147,A10,'Daily Plan'!$F$5:$F$147,"<>Rest") -> 10 | E10: =COUNTIFS('Daily Plan'!$B$5:$B$147,A10,'Daily Plan'!$K$5:$K$147,"Yes")+COUNTIFS('Daily Plan'!$B$5:$B$147,A10,'Daily Plan'!$K$5:$K$147,"Partial") -> 0 | F10: =IFERROR(E10/D10,"") -> 0 | G10: =SUMIFS('Daily Plan'!$I$5:$I$147,'Daily Plan'!$B$5:$B$147,A10,'Daily Plan'!$F$5:$F$147,"Run",'Daily Plan'!$J$5:$J$147,"min") -> 145 | H10: =SUMIFS('Daily Plan'!$L$5:$L$147,'Daily Plan'!$B$5:$B$147,A10,'Daily Plan'!$F$5:$F$147,"Run") -> 0 | I10: 70 | J10: =IFERROR(INDEX('Daily Plan'!$L$5:$L$147,MATCH(1,INDEX(('Daily Plan'!$B$5:$B$147=A10)*('Daily Plan'!$C$5:$C$147="Saturday")*('Daily Plan'!$F$5:$F$147="Run"),0),0)),"") -> 0 | K10: =IFERROR(AVERAGEIFS('Daily Plan'!$N$5:$N$147,'Daily Plan'!$B$5:$B$147,A10,'Daily Plan'!$F$5:$F$147,"Run"),"") | L10: =IFERROR(AVERAGEIFS('Daily Log'!$H$5:$H$106,'Daily Log'!$B$5:$B$106,A10),"") | M10: =IFERROR(AVERAGEIFS('Daily Log'!$I$5:$I$106,'Daily Log'!$B$5:$B$106,A10),"") | N10: =IF(COUNTIFS('Daily Log'!$B$5:$B$106,A10,'Daily Log'!$K$5:$K$106,">=0")=0,"",_xlfn.MAXIFS('Daily Log'!$K$5:$K$106,'Daily Log'!$B$5:$B$106,A10)) | O10: =IFERROR(AVERAGEIFS('Daily Log'!$M$5:$M$106,'Daily Log'!$B$5:$B$106,A10),"") | P10: =IFERROR(AVERAGEIFS('Daily Log'!$N$5:$N$106,'Daily Log'!$B$5:$B$106,A10),"") | Q10: =IFERROR(AVERAGEIFS('Daily Log'!$E$5:$E$106,'Daily Log'!$B$5:$B$106,A10),"") | R10: =IF(OR(Q10="",Q9=""),"",Q10-Q9) | V10: =IF(E10=0,"",IF(OR(AND(N10<>"",N10>=4),AND(F10<>"",F10<0.6),AND(L10<>"",L10<6)),"Red: step back",IF(OR(AND(F10<>"",F10<0.85),AND(K10<>"",K10>=5),AND(N10<>"",N10>=3),AND(L10<>"",L10<6.5),AND(O10<>"",O10<3),AND(P10<>"",P10<3)),"Amber: repeat the week","Green: progress")))
A11: 6 | B11: 46363 | C11: Aerobic development | D11: =COUNTIFS('Daily Plan'!$B$5:$B$147,A11,'Daily Plan'!$F$5:$F$147,"<>Rest") -> 10 | E11: =COUNTIFS('Daily Plan'!$B$5:$B$147,A11,'Daily Plan'!$K$5:$K$147,"Yes")+COUNTIFS('Daily Plan'!$B$5:$B$147,A11,'Daily Plan'!$K$5:$K$147,"Partial") -> 0 | F11: =IFERROR(E11/D11,"") -> 0 | G11: =SUMIFS('Daily Plan'!$I$5:$I$147,'Daily Plan'!$B$5:$B$147,A11,'Daily Plan'!$F$5:$F$147,"Run",'Daily Plan'!$J$5:$J$147,"min") -> 160 | H11: =SUMIFS('Daily Plan'!$L$5:$L$147,'Daily Plan'!$B$5:$B$147,A11,'Daily Plan'!$F$5:$F$147,"Run") -> 0 | I11: 80 | J11: =IFERROR(INDEX('Daily Plan'!$L$5:$L$147,MATCH(1,INDEX(('Daily Plan'!$B$5:$B$147=A11)*('Daily Plan'!$C$5:$C$147="Saturday")*('Daily Plan'!$F$5:$F$147="Run"),0),0)),"") -> 0 | K11: =IFERROR(AVERAGEIFS('Daily Plan'!$N$5:$N$147,'Daily Plan'!$B$5:$B$147,A11,'Daily Plan'!$F$5:$F$147,"Run"),"") | L11: =IFERROR(AVERAGEIFS('Daily Log'!$H$5:$H$106,'Daily Log'!$B$5:$B$106,A11),"") | M11: =IFERROR(AVERAGEIFS('Daily Log'!$I$5:$I$106,'Daily Log'!$B$5:$B$106,A11),"") | N11: =IF(COUNTIFS('Daily Log'!$B$5:$B$106,A11,'Daily Log'!$K$5:$K$106,">=0")=0,"",_xlfn.MAXIFS('Daily Log'!$K$5:$K$106,'Daily Log'!$B$5:$B$106,A11)) | O11: =IFERROR(AVERAGEIFS('Daily Log'!$M$5:$M$106,'Daily Log'!$B$5:$B$106,A11),"") | P11: =IFERROR(AVERAGEIFS('Daily Log'!$N$5:$N$106,'Daily Log'!$B$5:$B$106,A11),"") | Q11: =IFERROR(AVERAGEIFS('Daily Log'!$E$5:$E$106,'Daily Log'!$B$5:$B$106,A11),"") | R11: =IF(OR(Q11="",Q10=""),"",Q11-Q10) | V11: =IF(E11=0,"",IF(OR(AND(N11<>"",N11>=4),AND(F11<>"",F11<0.6),AND(L11<>"",L11<6)),"Red: step back",IF(OR(AND(F11<>"",F11<0.85),AND(K11<>"",K11>=5),AND(N11<>"",N11>=3),AND(L11<>"",L11<6.5),AND(O11<>"",O11<3),AND(P11<>"",P11<3)),"Amber: repeat the week","Green: progress")))
A12: 7 | B12: 46370 | C12: Aerobic development | D12: =COUNTIFS('Daily Plan'!$B$5:$B$147,A12,'Daily Plan'!$F$5:$F$147,"<>Rest") -> 10 | E12: =COUNTIFS('Daily Plan'!$B$5:$B$147,A12,'Daily Plan'!$K$5:$K$147,"Yes")+COUNTIFS('Daily Plan'!$B$5:$B$147,A12,'Daily Plan'!$K$5:$K$147,"Partial") -> 0 | F12: =IFERROR(E12/D12,"") -> 0 | G12: =SUMIFS('Daily Plan'!$I$5:$I$147,'Daily Plan'!$B$5:$B$147,A12,'Daily Plan'!$F$5:$F$147,"Run",'Daily Plan'!$J$5:$J$147,"min") -> 175 | H12: =SUMIFS('Daily Plan'!$L$5:$L$147,'Daily Plan'!$B$5:$B$147,A12,'Daily Plan'!$F$5:$F$147,"Run") -> 0 | I12: 90 | J12: =IFERROR(INDEX('Daily Plan'!$L$5:$L$147,MATCH(1,INDEX(('Daily Plan'!$B$5:$B$147=A12)*('Daily Plan'!$C$5:$C$147="Saturday")*('Daily Plan'!$F$5:$F$147="Run"),0),0)),"") -> 0 | K12: =IFERROR(AVERAGEIFS('Daily Plan'!$N$5:$N$147,'Daily Plan'!$B$5:$B$147,A12,'Daily Plan'!$F$5:$F$147,"Run"),"") | L12: =IFERROR(AVERAGEIFS('Daily Log'!$H$5:$H$106,'Daily Log'!$B$5:$B$106,A12),"") | M12: =IFERROR(AVERAGEIFS('Daily Log'!$I$5:$I$106,'Daily Log'!$B$5:$B$106,A12),"") | N12: =IF(COUNTIFS('Daily Log'!$B$5:$B$106,A12,'Daily Log'!$K$5:$K$106,">=0")=0,"",_xlfn.MAXIFS('Daily Log'!$K$5:$K$106,'Daily Log'!$B$5:$B$106,A12)) | O12: =IFERROR(AVERAGEIFS('Daily Log'!$M$5:$M$106,'Daily Log'!$B$5:$B$106,A12),"") | P12: =IFERROR(AVERAGEIFS('Daily Log'!$N$5:$N$106,'Daily Log'!$B$5:$B$106,A12),"") | Q12: =IFERROR(AVERAGEIFS('Daily Log'!$E$5:$E$106,'Daily Log'!$B$5:$B$106,A12),"") | R12: =IF(OR(Q12="",Q11=""),"",Q12-Q11) | V12: =IF(E12=0,"",IF(OR(AND(N12<>"",N12>=4),AND(F12<>"",F12<0.6),AND(L12<>"",L12<6)),"Red: step back",IF(OR(AND(F12<>"",F12<0.85),AND(K12<>"",K12>=5),AND(N12<>"",N12>=3),AND(L12<>"",L12<6.5),AND(O12<>"",O12<3),AND(P12<>"",P12<3)),"Amber: repeat the week","Green: progress")))
A13: 8 | B13: 46377 | C13: Aerobic development | D13: =COUNTIFS('Daily Plan'!$B$5:$B$147,A13,'Daily Plan'!$F$5:$F$147,"<>Rest") -> 10 | E13: =COUNTIFS('Daily Plan'!$B$5:$B$147,A13,'Daily Plan'!$K$5:$K$147,"Yes")+COUNTIFS('Daily Plan'!$B$5:$B$147,A13,'Daily Plan'!$K$5:$K$147,"Partial") -> 0 | F13: =IFERROR(E13/D13,"") -> 0 | G13: =SUMIFS('Daily Plan'!$I$5:$I$147,'Daily Plan'!$B$5:$B$147,A13,'Daily Plan'!$F$5:$F$147,"Run",'Daily Plan'!$J$5:$J$147,"min") -> 155 | H13: =SUMIFS('Daily Plan'!$L$5:$L$147,'Daily Plan'!$B$5:$B$147,A13,'Daily Plan'!$F$5:$F$147,"Run") -> 0 | I13: 70 | J13: =IFERROR(INDEX('Daily Plan'!$L$5:$L$147,MATCH(1,INDEX(('Daily Plan'!$B$5:$B$147=A13)*('Daily Plan'!$C$5:$C$147="Saturday")*('Daily Plan'!$F$5:$F$147="Run"),0),0)),"") -> 0 | K13: =IFERROR(AVERAGEIFS('Daily Plan'!$N$5:$N$147,'Daily Plan'!$B$5:$B$147,A13,'Daily Plan'!$F$5:$F$147,"Run"),"") | L13: =IFERROR(AVERAGEIFS('Daily Log'!$H$5:$H$106,'Daily Log'!$B$5:$B$106,A13),"") | M13: =IFERROR(AVERAGEIFS('Daily Log'!$I$5:$I$106,'Daily Log'!$B$5:$B$106,A13),"") | N13: =IF(COUNTIFS('Daily Log'!$B$5:$B$106,A13,'Daily Log'!$K$5:$K$106,">=0")=0,"",_xlfn.MAXIFS('Daily Log'!$K$5:$K$106,'Daily Log'!$B$5:$B$106,A13)) | O13: =IFERROR(AVERAGEIFS('Daily Log'!$M$5:$M$106,'Daily Log'!$B$5:$B$106,A13),"") | P13: =IFERROR(AVERAGEIFS('Daily Log'!$N$5:$N$106,'Daily Log'!$B$5:$B$106,A13),"") | Q13: =IFERROR(AVERAGEIFS('Daily Log'!$E$5:$E$106,'Daily Log'!$B$5:$B$106,A13),"") | R13: =IF(OR(Q13="",Q12=""),"",Q13-Q12) | V13: =IF(E13=0,"",IF(OR(AND(N13<>"",N13>=4),AND(F13<>"",F13<0.6),AND(L13<>"",L13<6)),"Red: step back",IF(OR(AND(F13<>"",F13<0.85),AND(K13<>"",K13>=5),AND(N13<>"",N13>=3),AND(L13<>"",L13<6.5),AND(O13<>"",O13<3),AND(P13<>"",P13<3)),"Amber: repeat the week","Green: progress")))
A14: 9 | B14: 46384 | C14: Race-specific endurance | D14: =COUNTIFS('Daily Plan'!$B$5:$B$147,A14,'Daily Plan'!$F$5:$F$147,"<>Rest") -> 10 | E14: =COUNTIFS('Daily Plan'!$B$5:$B$147,A14,'Daily Plan'!$K$5:$K$147,"Yes")+COUNTIFS('Daily Plan'!$B$5:$B$147,A14,'Daily Plan'!$K$5:$K$147,"Partial") -> 0 | F14: =IFERROR(E14/D14,"") -> 0 | G14: =SUMIFS('Daily Plan'!$I$5:$I$147,'Daily Plan'!$B$5:$B$147,A14,'Daily Plan'!$F$5:$F$147,"Run",'Daily Plan'!$J$5:$J$147,"min") -> 195 | H14: =SUMIFS('Daily Plan'!$L$5:$L$147,'Daily Plan'!$B$5:$B$147,A14,'Daily Plan'!$F$5:$F$147,"Run") -> 0 | I14: 105 | J14: =IFERROR(INDEX('Daily Plan'!$L$5:$L$147,MATCH(1,INDEX(('Daily Plan'!$B$5:$B$147=A14)*('Daily Plan'!$C$5:$C$147="Saturday")*('Daily Plan'!$F$5:$F$147="Run"),0),0)),"") -> 0 | K14: =IFERROR(AVERAGEIFS('Daily Plan'!$N$5:$N$147,'Daily Plan'!$B$5:$B$147,A14,'Daily Plan'!$F$5:$F$147,"Run"),"") | L14: =IFERROR(AVERAGEIFS('Daily Log'!$H$5:$H$106,'Daily Log'!$B$5:$B$106,A14),"") | M14: =IFERROR(AVERAGEIFS('Daily Log'!$I$5:$I$106,'Daily Log'!$B$5:$B$106,A14),"") | N14: =IF(COUNTIFS('Daily Log'!$B$5:$B$106,A14,'Daily Log'!$K$5:$K$106,">=0")=0,"",_xlfn.MAXIFS('Daily Log'!$K$5:$K$106,'Daily Log'!$B$5:$B$106,A14)) | O14: =IFERROR(AVERAGEIFS('Daily Log'!$M$5:$M$106,'Daily Log'!$B$5:$B$106,A14),"") | P14: =IFERROR(AVERAGEIFS('Daily Log'!$N$5:$N$106,'Daily Log'!$B$5:$B$106,A14),"") | Q14: =IFERROR(AVERAGEIFS('Daily Log'!$E$5:$E$106,'Daily Log'!$B$5:$B$106,A14),"") | R14: =IF(OR(Q14="",Q13=""),"",Q14-Q13) | V14: =IF(E14=0,"",IF(OR(AND(N14<>"",N14>=4),AND(F14<>"",F14<0.6),AND(L14<>"",L14<6)),"Red: step back",IF(OR(AND(F14<>"",F14<0.85),AND(K14<>"",K14>=5),AND(N14<>"",N14>=3),AND(L14<>"",L14<6.5),AND(O14<>"",O14<3),AND(P14<>"",P14<3)),"Amber: repeat the week","Green: progress")))
A15: 10 | B15: 46391 | C15: Race-specific endurance | D15: =COUNTIFS('Daily Plan'!$B$5:$B$147,A15,'Daily Plan'!$F$5:$F$147,"<>Rest") -> 10 | E15: =COUNTIFS('Daily Plan'!$B$5:$B$147,A15,'Daily Plan'!$K$5:$K$147,"Yes")+COUNTIFS('Daily Plan'!$B$5:$B$147,A15,'Daily Plan'!$K$5:$K$147,"Partial") -> 0 | F15: =IFERROR(E15/D15,"") -> 0 | G15: =SUMIFS('Daily Plan'!$I$5:$I$147,'Daily Plan'!$B$5:$B$147,A15,'Daily Plan'!$F$5:$F$147,"Run",'Daily Plan'!$J$5:$J$147,"min") -> 215 | H15: =SUMIFS('Daily Plan'!$L$5:$L$147,'Daily Plan'!$B$5:$B$147,A15,'Daily Plan'!$F$5:$F$147,"Run") -> 0 | I15: 120 | J15: =IFERROR(INDEX('Daily Plan'!$L$5:$L$147,MATCH(1,INDEX(('Daily Plan'!$B$5:$B$147=A15)*('Daily Plan'!$C$5:$C$147="Saturday")*('Daily Plan'!$F$5:$F$147="Run"),0),0)),"") -> 0 | K15: =IFERROR(AVERAGEIFS('Daily Plan'!$N$5:$N$147,'Daily Plan'!$B$5:$B$147,A15,'Daily Plan'!$F$5:$F$147,"Run"),"") | L15: =IFERROR(AVERAGEIFS('Daily Log'!$H$5:$H$106,'Daily Log'!$B$5:$B$106,A15),"") | M15: =IFERROR(AVERAGEIFS('Daily Log'!$I$5:$I$106,'Daily Log'!$B$5:$B$106,A15),"") | N15: =IF(COUNTIFS('Daily Log'!$B$5:$B$106,A15,'Daily Log'!$K$5:$K$106,">=0")=0,"",_xlfn.MAXIFS('Daily Log'!$K$5:$K$106,'Daily Log'!$B$5:$B$106,A15)) | O15: =IFERROR(AVERAGEIFS('Daily Log'!$M$5:$M$106,'Daily Log'!$B$5:$B$106,A15),"") | P15: =IFERROR(AVERAGEIFS('Daily Log'!$N$5:$N$106,'Daily Log'!$B$5:$B$106,A15),"") | Q15: =IFERROR(AVERAGEIFS('Daily Log'!$E$5:$E$106,'Daily Log'!$B$5:$B$106,A15),"") | R15: =IF(OR(Q15="",Q14=""),"",Q15-Q14) | V15: =IF(E15=0,"",IF(OR(AND(N15<>"",N15>=4),AND(F15<>"",F15<0.6),AND(L15<>"",L15<6)),"Red: step back",IF(OR(AND(F15<>"",F15<0.85),AND(K15<>"",K15>=5),AND(N15<>"",N15>=3),AND(L15<>"",L15<6.5),AND(O15<>"",O15<3),AND(P15<>"",P15<3)),"Amber: repeat the week","Green: progress")))
A16: 11 | B16: 46398 | C16: Race-specific endurance | D16: =COUNTIFS('Daily Plan'!$B$5:$B$147,A16,'Daily Plan'!$F$5:$F$147,"<>Rest") -> 10 | E16: =COUNTIFS('Daily Plan'!$B$5:$B$147,A16,'Daily Plan'!$K$5:$K$147,"Yes")+COUNTIFS('Daily Plan'!$B$5:$B$147,A16,'Daily Plan'!$K$5:$K$147,"Partial") -> 0 | F16: =IFERROR(E16/D16,"") -> 0 | G16: =SUMIFS('Daily Plan'!$I$5:$I$147,'Daily Plan'!$B$5:$B$147,A16,'Daily Plan'!$F$5:$F$147,"Run",'Daily Plan'!$J$5:$J$147,"min") -> 180 | H16: =SUMIFS('Daily Plan'!$L$5:$L$147,'Daily Plan'!$B$5:$B$147,A16,'Daily Plan'!$F$5:$F$147,"Run") -> 0 | I16: 90 | J16: =IFERROR(INDEX('Daily Plan'!$L$5:$L$147,MATCH(1,INDEX(('Daily Plan'!$B$5:$B$147=A16)*('Daily Plan'!$C$5:$C$147="Saturday")*('Daily Plan'!$F$5:$F$147="Run"),0),0)),"") -> 0 | K16: =IFERROR(AVERAGEIFS('Daily Plan'!$N$5:$N$147,'Daily Plan'!$B$5:$B$147,A16,'Daily Plan'!$F$5:$F$147,"Run"),"") | L16: =IFERROR(AVERAGEIFS('Daily Log'!$H$5:$H$106,'Daily Log'!$B$5:$B$106,A16),"") | M16: =IFERROR(AVERAGEIFS('Daily Log'!$I$5:$I$106,'Daily Log'!$B$5:$B$106,A16),"") | N16: =IF(COUNTIFS('Daily Log'!$B$5:$B$106,A16,'Daily Log'!$K$5:$K$106,">=0")=0,"",_xlfn.MAXIFS('Daily Log'!$K$5:$K$106,'Daily Log'!$B$5:$B$106,A16)) | O16: =IFERROR(AVERAGEIFS('Daily Log'!$M$5:$M$106,'Daily Log'!$B$5:$B$106,A16),"") | P16: =IFERROR(AVERAGEIFS('Daily Log'!$N$5:$N$106,'Daily Log'!$B$5:$B$106,A16),"") | Q16: =IFERROR(AVERAGEIFS('Daily Log'!$E$5:$E$106,'Daily Log'!$B$5:$B$106,A16),"") | R16: =IF(OR(Q16="",Q15=""),"",Q16-Q15) | V16: =IF(E16=0,"",IF(OR(AND(N16<>"",N16>=4),AND(F16<>"",F16<0.6),AND(L16<>"",L16<6)),"Red: step back",IF(OR(AND(F16<>"",F16<0.85),AND(K16<>"",K16>=5),AND(N16<>"",N16>=3),AND(L16<>"",L16<6.5),AND(O16<>"",O16<3),AND(P16<>"",P16<3)),"Amber: repeat the week","Green: progress")))
A17: 12 | B17: 46405 | C17: Peak | D17: =COUNTIFS('Daily Plan'!$B$5:$B$147,A17,'Daily Plan'!$F$5:$F$147,"<>Rest") -> 10 | E17: =COUNTIFS('Daily Plan'!$B$5:$B$147,A17,'Daily Plan'!$K$5:$K$147,"Yes")+COUNTIFS('Daily Plan'!$B$5:$B$147,A17,'Daily Plan'!$K$5:$K$147,"Partial") -> 0 | F17: =IFERROR(E17/D17,"") -> 0 | G17: =SUMIFS('Daily Plan'!$I$5:$I$147,'Daily Plan'!$B$5:$B$147,A17,'Daily Plan'!$F$5:$F$147,"Run",'Daily Plan'!$J$5:$J$147,"min") -> 245 | H17: =SUMIFS('Daily Plan'!$L$5:$L$147,'Daily Plan'!$B$5:$B$147,A17,'Daily Plan'!$F$5:$F$147,"Run") -> 0 | I17: 150 | J17: =IFERROR(INDEX('Daily Plan'!$L$5:$L$147,MATCH(1,INDEX(('Daily Plan'!$B$5:$B$147=A17)*('Daily Plan'!$C$5:$C$147="Saturday")*('Daily Plan'!$F$5:$F$147="Run"),0),0)),"") -> 0 | K17: =IFERROR(AVERAGEIFS('Daily Plan'!$N$5:$N$147,'Daily Plan'!$B$5:$B$147,A17,'Daily Plan'!$F$5:$F$147,"Run"),"") | L17: =IFERROR(AVERAGEIFS('Daily Log'!$H$5:$H$106,'Daily Log'!$B$5:$B$106,A17),"") | M17: =IFERROR(AVERAGEIFS('Daily Log'!$I$5:$I$106,'Daily Log'!$B$5:$B$106,A17),"") | N17: =IF(COUNTIFS('Daily Log'!$B$5:$B$106,A17,'Daily Log'!$K$5:$K$106,">=0")=0,"",_xlfn.MAXIFS('Daily Log'!$K$5:$K$106,'Daily Log'!$B$5:$B$106,A17)) | O17: =IFERROR(AVERAGEIFS('Daily Log'!$M$5:$M$106,'Daily Log'!$B$5:$B$106,A17),"") | P17: =IFERROR(AVERAGEIFS('Daily Log'!$N$5:$N$106,'Daily Log'!$B$5:$B$106,A17),"") | Q17: =IFERROR(AVERAGEIFS('Daily Log'!$E$5:$E$106,'Daily Log'!$B$5:$B$106,A17),"") | R17: =IF(OR(Q17="",Q16=""),"",Q17-Q16) | V17: =IF(E17=0,"",IF(OR(AND(N17<>"",N17>=4),AND(F17<>"",F17<0.6),AND(L17<>"",L17<6)),"Red: step back",IF(OR(AND(F17<>"",F17<0.85),AND(K17<>"",K17>=5),AND(N17<>"",N17>=3),AND(L17<>"",L17<6.5),AND(O17<>"",O17<3),AND(P17<>"",P17<3)),"Amber: repeat the week","Green: progress")))
A18: 13 | B18: 46412 | C18: Taper | D18: =COUNTIFS('Daily Plan'!$B$5:$B$147,A18,'Daily Plan'!$F$5:$F$147,"<>Rest") -> 9 | E18: =COUNTIFS('Daily Plan'!$B$5:$B$147,A18,'Daily Plan'!$K$5:$K$147,"Yes")+COUNTIFS('Daily Plan'!$B$5:$B$147,A18,'Daily Plan'!$K$5:$K$147,"Partial") -> 0 | F18: =IFERROR(E18/D18,"") -> 0 | G18: =SUMIFS('Daily Plan'!$I$5:$I$147,'Daily Plan'!$B$5:$B$147,A18,'Daily Plan'!$F$5:$F$147,"Run",'Daily Plan'!$J$5:$J$147,"min") -> 175 | H18: =SUMIFS('Daily Plan'!$L$5:$L$147,'Daily Plan'!$B$5:$B$147,A18,'Daily Plan'!$F$5:$F$147,"Run") -> 0 | I18: 90 | J18: =IFERROR(INDEX('Daily Plan'!$L$5:$L$147,MATCH(1,INDEX(('Daily Plan'!$B$5:$B$147=A18)*('Daily Plan'!$C$5:$C$147="Saturday")*('Daily Plan'!$F$5:$F$147="Run"),0),0)),"") -> 0 | K18: =IFERROR(AVERAGEIFS('Daily Plan'!$N$5:$N$147,'Daily Plan'!$B$5:$B$147,A18,'Daily Plan'!$F$5:$F$147,"Run"),"") | L18: =IFERROR(AVERAGEIFS('Daily Log'!$H$5:$H$106,'Daily Log'!$B$5:$B$106,A18),"") | M18: =IFERROR(AVERAGEIFS('Daily Log'!$I$5:$I$106,'Daily Log'!$B$5:$B$106,A18),"") | N18: =IF(COUNTIFS('Daily Log'!$B$5:$B$106,A18,'Daily Log'!$K$5:$K$106,">=0")=0,"",_xlfn.MAXIFS('Daily Log'!$K$5:$K$106,'Daily Log'!$B$5:$B$106,A18)) | O18: =IFERROR(AVERAGEIFS('Daily Log'!$M$5:$M$106,'Daily Log'!$B$5:$B$106,A18),"") | P18: =IFERROR(AVERAGEIFS('Daily Log'!$N$5:$N$106,'Daily Log'!$B$5:$B$106,A18),"") | Q18: =IFERROR(AVERAGEIFS('Daily Log'!$E$5:$E$106,'Daily Log'!$B$5:$B$106,A18),"") | R18: =IF(OR(Q18="",Q17=""),"",Q18-Q17) | V18: =IF(E18=0,"",IF(OR(AND(N18<>"",N18>=4),AND(F18<>"",F18<0.6),AND(L18<>"",L18<6)),"Red: step back",IF(OR(AND(F18<>"",F18<0.85),AND(K18<>"",K18>=5),AND(N18<>"",N18>=3),AND(L18<>"",L18<6.5),AND(O18<>"",O18<3),AND(P18<>"",P18<3)),"Amber: repeat the week","Green: progress")))
A19: 14 | B19: 46419 | C19: Race week | D19: =COUNTIFS('Daily Plan'!$B$5:$B$147,A19,'Daily Plan'!$F$5:$F$147,"<>Rest") -> 8 | E19: =COUNTIFS('Daily Plan'!$B$5:$B$147,A19,'Daily Plan'!$K$5:$K$147,"Yes")+COUNTIFS('Daily Plan'!$B$5:$B$147,A19,'Daily Plan'!$K$5:$K$147,"Partial") -> 0 | F19: =IFERROR(E19/D19,"") -> 0 | G19: =SUMIFS('Daily Plan'!$I$5:$I$147,'Daily Plan'!$B$5:$B$147,A19,'Daily Plan'!$F$5:$F$147,"Run",'Daily Plan'!$J$5:$J$147,"min") -> 50 | H19: =SUMIFS('Daily Plan'!$L$5:$L$147,'Daily Plan'!$B$5:$B$147,A19,'Daily Plan'!$F$5:$F$147,"Run") -> 0 | J19: =IFERROR(INDEX('Daily Plan'!$L$5:$L$147,MATCH(1,INDEX(('Daily Plan'!$B$5:$B$147=A19)*('Daily Plan'!$C$5:$C$147="Saturday")*('Daily Plan'!$F$5:$F$147="Run"),0),0)),"") | K19: =IFERROR(AVERAGEIFS('Daily Plan'!$N$5:$N$147,'Daily Plan'!$B$5:$B$147,A19,'Daily Plan'!$F$5:$F$147,"Run"),"") | L19: =IFERROR(AVERAGEIFS('Daily Log'!$H$5:$H$106,'Daily Log'!$B$5:$B$106,A19),"") | M19: =IFERROR(AVERAGEIFS('Daily Log'!$I$5:$I$106,'Daily Log'!$B$5:$B$106,A19),"") | N19: =IF(COUNTIFS('Daily Log'!$B$5:$B$106,A19,'Daily Log'!$K$5:$K$106,">=0")=0,"",_xlfn.MAXIFS('Daily Log'!$K$5:$K$106,'Daily Log'!$B$5:$B$106,A19)) | O19: =IFERROR(AVERAGEIFS('Daily Log'!$M$5:$M$106,'Daily Log'!$B$5:$B$106,A19),"") | P19: =IFERROR(AVERAGEIFS('Daily Log'!$N$5:$N$106,'Daily Log'!$B$5:$B$106,A19),"") | Q19: =IFERROR(AVERAGEIFS('Daily Log'!$E$5:$E$106,'Daily Log'!$B$5:$B$106,A19),"") | R19: =IF(OR(Q19="",Q18=""),"",Q19-Q18) | V19: =IF(E19=0,"",IF(OR(AND(N19<>"",N19>=4),AND(F19<>"",F19<0.6),AND(L19<>"",L19<6)),"Red: step back",IF(OR(AND(F19<>"",F19<0.85),AND(K19<>"",K19>=5),AND(N19<>"",N19>=3),AND(L19<>"",L19<6.5),AND(O19<>"",O19<3),AND(P19<>"",P19<3)),"Amber: repeat the week","Green: progress")))
A21: Decision rules: Red if max pain ≥ 4, completion < 60% or sleep < 6 h. Amber if completion < 85%, run RPE ≥ 5, pain 3, sleep < 6.5 h, or energy or mood < 3. Otherwise Green. Read the pattern, not one number.

Sheet Week Plan
A1: Fourteen-week overview
A2: Run time includes walking intervals. 1:2 = run 1 min, walk 2 min.
A4: Week | B4: Starts | C4: Phase | D4: Run:walk | E4: Tue (min) | F4: Fri (min) | G4: Sat long (min) | H4: Run time (min) | I4: Longest (≈ km) | J4: Strength | K4: Swims (optional) | L4: Objective
A5: 0 | B5: 46324 | C5: Foundation | D5: 1:2 | E5: 0 | F5: 30 | G5: 40 | H5: =0+30+40 -> 70 | I5: 3 | J5: 0 | K5: 100 m continuous | L5: Start the habit: first run-walks, first swim, learn the routines.
A6: 1 | B6: 46328 | C6: Foundation | D6: 1:2 | E6: 30 | F6: 30 | G6: 45 | H6: =30+30+45 -> 105 | I6: 4 | J6: 2 | K6: 8 × 50 m; 100 m continuous | L6: Get the legs used to regular impact with short run intervals.
A7: 2 | B7: 46335 | C7: Foundation | D7: 1:1 | E7: 35 | F7: 30 | G7: 50 | H7: =35+30+50 -> 115 | I7: 5 | J7: 2 | K7: 6 × 75 m; 125 m continuous | L7: Run 1 minute, walk 1 minute; long session to 50 minutes.
A8: 3 | B8: 46342 | C8: Foundation | D8: 2:1 | E8: 35 | F8: 35 | G8: 60 | H8: =35+35+60 -> 130 | I8: 6 | J8: 2 | K8: 5 × 100 m; 150 m continuous | L8: Double the run intervals to 2 minutes; first 60-minute session.
A9: 4 | B9: 46349 | C9: Foundation | D9: 2:1 | E9: 25 | F9: 5 km test | G9: 45 | H9: =25+50+45 -> 120 | I9: 4 | J9: 2 | K9: 4 × 100 m; 200 m continuous | L9: Easier week and the first 5 km test. Cutback week: about 15% less running, strength at 2 sets.
A10: 5 | B10: 46356 | C10: Aerobic development | D10: 3:1 | E10: 40 | F10: 35 | G10: 70 | H10: =40+35+70 -> 145 | I10: 7 | J10: 2 | K10: 4 × 150 m; 250 m continuous | L10: Run 3 minutes at a time; first relaxed strides.
A11: 6 | B11: 46363 | C11: Aerobic development | D11: 4:1 | E11: 40 | F11: 40 | G11: 80 | H11: =40+40+80 -> 160 | I11: 8 | J11: 2 | K11: 3 × 200 m; 300 m continuous | L11: Run 4 minutes at a time; long session to 80 minutes.
A12: 7 | B12: 46370 | C12: Aerobic development | D12: 4:1 | E12: 45 | F12: 40 | G12: 90 | H12: =45+40+90 -> 175 | I12: 9 | J12: 2 | K12: 4 × 200 m; 350 m continuous | L12: Introduce hill walking and jogging; long session to 90 minutes.
A13: 8 | B13: 46377 | C13: Aerobic development | D13: 5:1 | E13: 35 | F13: 5 km test | G13: 70 | H13: =35+50+70 -> 155 | I13: 7 | J13: 2 | K13: 3 × 200 m; 400 m continuous | L13: Easier week and the second 5 km test. Cutback week: strength at 2 sets; Christmas week is a good time for it.
A14: 9 | B14: 46384 | C14: Race-specific endurance | D14: 5:1 | E14: 45 | F14: 45 | G14: 105 | H14: =45+45+105 -> 195 | I14: 11 | J14: 2 | K14: 3 × 250 m; 450 m continuous | L14: First steady (moderate) running; long session over 100 minutes.
A15: 10 | B15: 46391 | C15: Race-specific endurance | D15: 6:1 | E15: 50 | F15: 45 | G15: 120 | H15: =50+45+120 -> 215 | I15: 12 | J15: 2 | K15: 2 × 400 m; 500 m continuous | L15: Hill repeats for the 8 km climb; long session to 2 hours.
A16: 11 | B16: 46398 | C16: Race-specific endurance | D16: 6:1 | E16: 5 km test | F16: 40 | G16: 90 | H16: =50+40+90 -> 180 | I16: 9 | J16: 2 | K16: 3 × 250 m; 600 m continuous | L16: Easier week and the deciding 5 km test. Cutback week: strength at 2 sets.
A17: 12 | B17: 46405 | C17: Peak | D17: 8:1 | E17: 50 | F17: 45 | G17: 150 | H17: =50+45+150 -> 245 | I17: 16 | J17: 2 | K17: 2 × 400 m; 600 m continuous | L17: Longest session: 2 h 30 min at race rhythm, with race fuelling. Sleep 8+ hours around the long run; Sunday swim very easy.
A18: 13 | B18: 46412 | C18: Taper | D18: 8:1 | E18: 45 | F18: 40 | G18: 90 | H18: =45+40+90 -> 175 | I18: 10 | J18: 1 | K18: 4 × 150 m; 700 m continuous | L18: Cut volume; keep a little race-effort running. Strength once, light; no new foods or shoes.
A19: 14 | B19: 46419 | C19: Race week | D19: 8:1 | E19: 30 | F19: 20 | G19: Race | H19: =30+20+0 -> 50 | I19: 21.1 | J19: 1 | K19: 6 × 50 m easy | L19: Rest, travel, race. No strength after Tuesday; travel to Moshi by Friday.

Sheet Strength
A1: Strength A (Wednesday) and B (Tuesday evening)
A2: Stop each set with 2–3 reps left (RPE 7). Cutback weeks 4, 8, 11: 2 sets. Week 13: A only, 2 sets. Week 14: upper body only.
A4: Session | B4: Exercise | C4: Sets × reps | D4: Rest | E4: Technique cues | F4: Progression
A5: A | B5: Sit-to-stand → squat | C5: 3 × 8–12 | D5: 60–90 s | E5: Feet hip-width, knees over toes, chest up, sit back | F5: Chair → no chair → backpack → 3 s lowering
A6: A | B6: Glute bridge | C6: 3 × 10–12 | D6: 60 s | E6: Ribs down, push through heels, 2 s squeeze | F6: Two legs → single leg
A7: A | B7: Step-up (or reverse lunge) | C7: 3 × 8 per leg | D7: 60–90 s | E7: Safe 20–30 cm step; no step: reverse lunge holding a wall | F7: Add the backpack
A8: A | B8: Hip hinge | C8: 3 × 10 | D8: 60 s | E8: Soft knees, flat back, hips back | F8: Good morning → single-leg RDL (hand on wall) → with backpack
A9: A | B9: Calf raise | C9: 3 × 12–15 | D9: 45–60 s | E9: Step edge, full range, 3 s down | F9: Two legs → single leg → single leg + backpack
A10: A | B10: Bent-knee calf raise | C10: 2 × 15 | D10: 45 s | E10: Knees bent 30° | F10: Single leg
A11: A | B11: Dead bug | C11: 3 × 8 per side | D11: 45 s | E11: Lower back pressed down | F11: Slower, straighter legs
A12: A | B12: Side plank | C12: 3 × 20–40 s per side | D12: 45 s | E12: Straight line ear-hip-ankle | F12: Knees → feet → top-leg lift
A13: A | B13: Pelvic-floor finisher | C13: 1 × 10 | D13: — | E13: Glute bridge with 5 s pelvic-floor squeeze | F13: Hold 8 s
A14: B | B14: Push-up | C14: 3 × 8–12 | D14: 60 s | E14: Body straight, elbows about 45° | F14: Wall → table → knees → full
A15: B | B15: Backpack bent-over row | C15: 3 × 10–12 | D15: 60 s | E15: Hinge, flat back, bag to lower ribs | F15: Heavier bag, 2 s squeeze
... A22: B | B22: Pelvic-floor finisher | C22: 10 squeezes | D22: — | E22: 5 s squeeze in a deep squat hold | F22: Hold 8 s
A25: Soreness or injury?
A26: Normal | B26: Dull, spread across a muscle, peaks 24–48 h after, eases as you warm up — train as planned
A27: Warning | B27: Sharp or pinpoint pain, pain on a bone, swelling, limping, pain at night, pain lasting 3+ days
A28: Rule | B28: Pain up to 3/10 that stays stable or eases: OK. Above 3 or rising: stop, 3 days walking/swimming only, physio if it lasts a week

Sheet Swim Plan
A1: Swim plan (optional) — from 100 m to 600–700 m continuous
A2: Wednesday repeats at RPE 4–5; Sunday continuous very easy (RPE 3–4). Never on a run day or a fast day.
A4: Week | B4: Wednesday main set | C4: Rest | D4: Wednesday total (m) | E4: Sunday continuous (m) | F4: Sunday total (m) | G4: Your longest non-stop (m)
A5: 0 | B5: — | E5: 100 | F5: =100+100+100+200+100 -> 600 | G5: =IFERROR(INDEX('Weekly Review'!T5:T19,MATCH(A5,'Weekly Review'!A5:A19,0)),"") -> 0
A6: 1 | B6: 8 × 50 m | C6: 40 s | D6: =100+100+50*8+100 -> 700 | E6: 100 | F6: =100+100+100+200+100 -> 600 | G6: =IFERROR(INDEX('Weekly Review'!T5:T19,MATCH(A6,'Weekly Review'!A5:A19,0)),"") -> 0
A7: 2 | B7: 6 × 75 m | C7: 40 s | D7: =100+100+75*6+100 -> 750 | E7: 125 | F7: =100+100+125+200+100 -> 625 | G7: =IFERROR(INDEX('Weekly Review'!T5:T19,MATCH(A7,'Weekly Review'!A5:A19,0)),"") -> 0
A8: 3 | B8: 5 × 100 m | C8: 40 s | D8: =100+100+100*5+100 -> 800 | E8: 150 | F8: =100+100+150+200+100 -> 650 | G8: =IFERROR(INDEX('Weekly Review'!T5:T19,MATCH(A8,'Weekly Review'!A5:A19,0)),"") -> 0
A9: 4 | B9: 4 × 100 m | C9: 30 s | D9: =100+100+100*4+100 -> 700 | E9: 200 | F9: =100+100+200+200+100 -> 700 | G9: =IFERROR(INDEX('Weekly Review'!T5:T19,MATCH(A9,'Weekly Review'!A5:A19,0)),"") -> 0
A10: 5 | B10: 4 × 150 m | C10: 45 s | D10: =100+100+150*4+100 -> 900 | E10: 250 | F10: =100+100+250+200+100 -> 750 | G10: =IFERROR(INDEX('Weekly Review'!T5:T19,MATCH(A10,'Weekly Review'!A5:A19,0)),"") -> 0
A11: 6 | B11: 3 × 200 m | C11: 45 s | D11: =100+100+200*3+100 -> 900 | E11: 300 | F11: =100+100+300+200+100 -> 800 | G11: =IFERROR(INDEX('Weekly Review'!T5:T19,MATCH(A11,'Weekly Review'!A5:A19,0)),"") -> 0
A12: 7 | B12: 4 × 200 m | C12: 40 s | D12: =100+100+200*4+100 -> 1100 | E12: 350 | F12: =100+100+350+200+100 -> 850 | G12: =IFERROR(INDEX('Weekly Review'!T5:T19,MATCH(A12,'Weekly Review'!A5:A19,0)),"") -> 0
A13: 8 | B13: 3 × 200 m | C13: 40 s | D13: =100+100+200*3+100 -> 900 | E13: 400 | F13: =100+100+400+200+100 -> 900 | G13: =IFERROR(INDEX('Weekly Review'!T5:T19,MATCH(A13,'Weekly Review'!A5:A19,0)),"") -> 0
A14: 9 | B14: 3 × 250 m | C14: 45 s | D14: =100+100+250*3+100 -> 1050 | E14: 450 | F14: =100+100+450+200+100 -> 950 | G14: =IFERROR(INDEX('Weekly Review'!T5:T19,MATCH(A14,'Weekly Review'!A5:A19,0)),"") -> 0
A15: 10 | B15: 2 × 400 m | C15: 60 s | D15: =100+100+400*2+100 -> 1100 | E15: 500 | F15: =100+100+500+200+100 -> 1000 | G15: =IFERROR(INDEX('Weekly Review'!T5:T19,MATCH(A15,'Weekly Review'!A5:A19,0)),"") -> 0
A16: 11 | B16: 3 × 250 m | C16: 45 s | D16: =100+100+250*3+100 -> 1050 | E16: 600 | F16: =100+100+600+200+100 -> 1100 | G16: =IFERROR(INDEX('Weekly Review'!T5:T19,MATCH(A16,'Weekly Review'!A5:A19,0)),"") -> 0
A17: 12 | B17: 2 × 400 m | C17: 60 s | D17: =100+100+400*2+100 -> 1100 | E17: 600 | F17: =100+100+600+200+100 -> 1100 | G17: =IFERROR(INDEX('Weekly Review'!T5:T19,MATCH(A17,'Weekly Review'!A5:A19,0)),"") -> 0
A18: 13 | B18: 4 × 150 m | C18: 40 s | D18: =100+100+150*4+100 -> 900 | E18: 700 | F18: =100+100+700+200+100 -> 1200 | G18: =IFERROR(INDEX('Weekly Review'!T5:T19,MATCH(A18,'Weekly Review'!A5:A19,0)),"") -> 0
A19: 14 | B19: 6 × 50 m easy | C19: 30 s | D19: =100+100+50*6+100 -> 600 | E19: Race | G19: =IFERROR(INDEX('Weekly Review'!T5:T19,MATCH(A19,'Weekly Review'!A5:A19,0)),"") -> 0
A21: Every swim: warm-up 4 × 25 m easy; drills 4 × 25 m (side kick, catch-up, fingertip drag, six-kick switch); main set; cool-down 50–100 m easy. Sunday adds 4 × 50 m relaxed after the continuous swim.

Sheet Foods
A1: Food values
A2: Typical values for the closest standard food; local recipes vary about ±15%. Edit to match your foods.
A4: Key | B4: Food | C4: Basis | D4: Divide by | E4: kcal | F4: Protein (g) | G4: Carbs (g) | H4: Fat (g)
A5: ugali | B5: ugali | C5: per 100 g | D5: 100 | E5: 115 | F5: 2.5 | G5: 25 | H5: 0.5
A6: rice | B6: rice (cooked) | C6: per 100 g | D6: 100 | E6: 130 | F6: 2.7 | G6: 28 | H6: 0.3
A7: sweet_potato | B7: viazi vitamu (boiled) | C7: per 100 g | D7: 100 | E7: 86 | F7: 1.6 | G7: 20 | H7: 0.1
A8: potato | B8: Irish potato (boiled) | C8: per 100 g | D8: 100 | E8: 87 | F8: 1.9 | G8: 20 | H8: 0.1
A9: plantain | B9: ndizi (boiled) | C9: per 100 g | D9: 100 | E9: 116 | F9: 0.8 | G9: 31 | H9: 0.2
A10: beans | B10: maharage (cooked) | C10: per 100 g | D10: 100 | E10: 127 | F10: 8.7 | G10: 23 | H10: 0.5
A11: lentils | B11: dengu (cooked) | C11: per 100 g | D11: 100 | E11: 116 | F11: 9 | G11: 20 | H11: 0.4
A12: chicken | B12: chicken, skinless | C12: per 100 g | D12: 100 | E12: 165 | F12: 31 | G12: 0 | H12: 3.6
A13: tilapia | B13: sato (tilapia) | C13: per 100 g | D13: 100 | E13: 128 | F13: 26 | G13: 0 | H13: 2.7
A14: beef | B14: lean beef | C14: per 100 g | D14: 100 | E14: 200 | F14: 28 | G14: 0 | H14: 9
A15: dagaa | B15: dagaa (dried) | C15: per 100 g | D15: 100 | E15: 330 | F15: 60 | G15: 0 | H15: 9
A16: sardines | B16: sardines (tinned, drained) | C16: per 100 g | D16: 100 | E16: 208 | F16: 25 | G16: 0 | H16: 11
... A40: soup_bowl | B40: clear soup, 300 ml bowl | C40: per unit | D40: 1 | E40: 60 | F40: 4 | G40: 6 | H40: 2

Sheet Meal Plan
A1: Seven-day Tanzanian meal plan
A2: Change a quantity (yellow) or a food key and the totals update. Keys are listed on the Foods sheet.
A4: Day | B4: Time | C4: Meal | D4: Food key | E4: Quantity | F4: Unit | G4: kcal | H4: Protein (g) | I4: Carbs (g) | J4: Fat (g) | K4: Note
A5: Monday (fast day) | B5: 04:30 | C5: Suhoor | D5: oats | E5: 50 | F5: g | G5: =E5/INDEX(Foods!$D$5:$D$40,MATCH(D5,Foods!$A$5:$A$40,0))*INDEX(Foods!$E$5:$E$40,MATCH(D5,Foods!$A$5:$A$40,0)) -> 190 | H5: =E5/INDEX(Foods!$D$5:$D$40,MATCH(D5,Foods!$A$5:$A$40,0))*INDEX(Foods!$F$5:$F$40,MATCH(D5,Foods!$A$5:$A$40,0)) -> 6.5 | I5: =E5/INDEX(Foods!$D$5:$D$40,MATCH(D5,Foods!$A$5:$A$40,0))*INDEX(Foods!$G$5:$G$40,MATCH(D5,Foods!$A$5:$A$40,0)) -> 33 | J5: =E5/INDEX(Foods!$D$5:$D$40,MATCH(D5,Foods!$A$5:$A$40,0))*INDEX(Foods!$H$5:$H$40,MATCH(D5,Foods!$A$5:$A$40,0)) -> 3.5 | K5: Oats cooked in the milk. Drink 600–800 ml water, sipped through the meal. Little salt.
A6: Monday (fast day) | B6: 04:30 | C6: Suhoor | D6: milk_250 | E6: 1 | F6: unit | G6: =E6/INDEX(Foods!$D$5:$D$40,MATCH(D6,Foods!$A$5:$A$40,0))*INDEX(Foods!$E$5:$E$40,MATCH(D6,Foods!$A$5:$A$40,0)) -> 150 | H6: =E6/INDEX(Foods!$D$5:$D$40,MATCH(D6,Foods!$A$5:$A$40,0))*INDEX(Foods!$F$5:$F$40,MATCH(D6,Foods!$A$5:$A$40,0)) -> 8 | I6: =E6/INDEX(Foods!$D$5:$D$40,MATCH(D6,Foods!$A$5:$A$40,0))*INDEX(Foods!$G$5:$G$40,MATCH(D6,Foods!$A$5:$A$40,0)) -> 12 | J6: =E6/INDEX(Foods!$D$5:$D$40,MATCH(D6,Foods!$A$5:$A$40,0))*INDEX(Foods!$H$5:$H$40,MATCH(D6,Foods!$A$5:$A$40,0)) -> 8
A7: Monday (fast day) | B7: 04:30 | C7: Suhoor | D7: egg | E7: 3 | F7: unit | G7: =E7/INDEX(Foods!$D$5:$D$40,MATCH(D7,Foods!$A$5:$A$40,0))*INDEX(Foods!$E$5:$E$40,MATCH(D7,Foods!$A$5:$A$40,0)) -> 216 | H7: =E7/INDEX(Foods!$D$5:$D$40,MATCH(D7,Foods!$A$5:$A$40,0))*INDEX(Foods!$F$5:$F$40,MATCH(D7,Foods!$A$5:$A$40,0)) -> 18.9 | I7: =E7/INDEX(Foods!$D$5:$D$40,MATCH(D7,Foods!$A$5:$A$40,0))*INDEX(Foods!$G$5:$G$40,MATCH(D7,Foods!$A$5:$A$40,0)) -> 1.2 | J7: =E7/INDEX(Foods!$D$5:$D$40,MATCH(D7,Foods!$A$5:$A$40,0))*INDEX(Foods!$H$5:$H$40,MATCH(D7,Foods!$A$5:$A$40,0)) -> 14.4
